<mujoco model="dual_panda_on_table_torque">
  <compiler angle="radian" meshdir="franka_emika_panda/assets" autolimits="true"/>
  <visual>
    <quality shadowsize="2048"/>
    <global offwidth="1920" offheight="1080"/>
    <map znear="0.01" zfar="50"/>
  </visual>
  <option integrator="implicitfast" timestep="0.002"/>

  <default>
    <default class="panda_arm">
      <material specular="0.5" shininess="0.25"/>
      <joint armature="0.1" damping="1" axis="0 0 1" range="-2.8973 2.8973"/>

      <default class="finger">
        <joint axis="0 1 0" type="slide" range="0 0.04"/>
      </default>

      <default class="visual">
        <geom type="mesh" contype="0" conaffinity="0" group="2"/>
      </default>

      <default class="collision">
        <geom type="mesh" group="3"/>
        <default class="fingertip_pad_collision_1">
          <geom type="box" size="0.0085 0.004 0.0085" pos="0 0.0055 0.0445"/>
        </default>
        <default class="fingertip_pad_collision_2">
          <geom type="box" size="0.003 0.002 0.003" pos="0.0055 0.002 0.05"/>
        </default>
        <default class="fingertip_pad_collision_3">
          <geom type="box" size="0.003 0.002 0.003" pos="-0.0055 0.002 0.05"/>
        </default>
        <default class="fingertip_pad_collision_4">
          <geom type="box" size="0.003 0.002 0.0035" pos="0.0055 0.002 0.0395"/>
        </default>
        <default class="fingertip_pad_collision_5">
          <geom type="box" size="0.003 0.002 0.0035" pos="-0.0055 0.002 0.0395"/>
        </default>
      </default>
    </default>
  </default>

  <asset>
    <material name="white" rgba="1 1 1 1"/>
    <material name="off_white" rgba="0.901961 0.921569 0.929412 1"/>
    <material name="black" rgba="0.25 0.25 0.25 1"/>
    <material name="green" rgba="0 1 0 1"/>
    <material name="light_blue" rgba="0.039216 0.541176 0.780392 1"/>
    <material name="table_mat" rgba="0.6 0.4 0.2 1"/>

    <mesh name="link0_c" file="link0.stl"/>
    <mesh name="link1_c" file="link1.stl"/>
    <mesh name="link2_c" file="link2.stl"/>
    <mesh name="link3_c" file="link3.stl"/>
    <mesh name="link4_c" file="link4.stl"/>
    <mesh name="link5_c0" file="link5_collision_0.obj"/>
    <mesh name="link5_c1" file="link5_collision_1.obj"/>
    <mesh name="link5_c2" file="link5_collision_2.obj"/>
    <mesh name="link6_c" file="link6.stl"/>
    <mesh name="link7_c" file="link7.stl"/>
    <mesh name="hand_c" file="hand.stl"/>

    <mesh file="link0_0.obj"/>
    <mesh file="link0_1.obj"/>
    <mesh file="link0_2.obj"/>
    <mesh file="link0_3.obj"/>
    <mesh file="link0_4.obj"/>
    <mesh file="link0_5.obj"/>
    <mesh file="link0_7.obj"/>
    <mesh file="link0_8.obj"/>
    <mesh file="link0_9.obj"/>
    <mesh file="link0_10.obj"/>
    <mesh file="link0_11.obj"/>
    <mesh file="link1.obj"/>
    <mesh file="link2.obj"/>
    <mesh file="link3_0.obj"/>
    <mesh file="link3_1.obj"/>
    <mesh file="link3_2.obj"/>
    <mesh file="link3_3.obj"/>
    <mesh file="link4_0.obj"/>
    <mesh file="link4_1.obj"/>
    <mesh file="link4_2.obj"/>
    <mesh file="link4_3.obj"/>
    <mesh file="link5_0.obj"/>
    <mesh file="link5_1.obj"/>
    <mesh file="link5_2.obj"/>
    <mesh file="link6_0.obj"/>
    <mesh file="link6_1.obj"/>
    <mesh file="link6_2.obj"/>
    <mesh file="link6_3.obj"/>
    <mesh file="link6_4.obj"/>
    <mesh file="link6_5.obj"/>
    <mesh file="link6_6.obj"/>
    <mesh file="link6_7.obj"/>
    <mesh file="link6_8.obj"/>
    <mesh file="link6_9.obj"/>
    <mesh file="link6_10.obj"/>
    <mesh file="link6_11.obj"/>
    <mesh file="link6_12.obj"/>
    <mesh file="link6_13.obj"/>
    <mesh file="link6_14.obj"/>
    <mesh file="link6_15.obj"/>
    <mesh file="link6_16.obj"/>
    <mesh file="link7_0.obj"/>
    <mesh file="link7_1.obj"/>
    <mesh file="link7_2.obj"/>
    <mesh file="link7_3.obj"/>
    <mesh file="link7_4.obj"/>
    <mesh file="link7_5.obj"/>
    <mesh file="link7_6.obj"/>
    <mesh file="link7_7.obj"/>
    <mesh file="hand_0.obj"/>
    <mesh file="hand_1.obj"/>
    <mesh file="hand_2.obj"/>
    <mesh file="hand_3.obj"/>
    <mesh file="hand_4.obj"/>
    <mesh file="finger_0.obj"/>
    <mesh file="finger_1.obj"/>

    <texture name="grid" type="2d" builtin="checker" rgb1=".1 .2 .3" rgb2=".2 .3 .4" width="300" height="300" mark="edge" markrgb=".8 .8 .8"/>
    <material name="grid_mat" texture="grid" texrepeat="1 1" texuniform="true"/>
    <texture name="skybox" type="skybox" builtin="gradient" rgb1=".3 .5 .7" rgb2="0 0 0" width="512" height="512"/>
  </asset>

  <worldbody>
    <light directional="true" diffuse=".2 .2 .2" specular="0 0 0" pos="0 0 5" dir="0 0 -1"/>
    <light directional="true" diffuse="0.8 0.8 0.8" specular="0.3 0.3 0.3" pos="0 0 4" dir="0 0 -1" castshadow="true"/>
    <light directional="true" diffuse="0.4 0.4 0.4" pos="1 1 3" dir="-1 -1 -1"/>
    <light directional="true" diffuse="0.4 0.4 0.4" pos="-1 1 3" dir="1 -1 -1"/>

    <geom name="floor" pos="0 0 0" size="0 0 .05" type="plane" material="grid_mat"/>

    <body name="table" pos="0 0 0.4">
      <geom name="table_top" type="box" size="0.8 0.6 0.02" material="table_mat" contype="1" conaffinity="1"/>
      <geom name="leg1" type="box" size="0.03 0.03 0.4" pos="-0.7 -0.5 -0.4" material="table_mat"/>
      <geom name="leg2" type="box" size="0.03 0.03 0.4" pos="0.7 -0.5 -0.4" material="table_mat"/>
      <geom name="leg3" type="box" size="0.03 0.03 0.4" pos="-0.7 0.5 -0.4" material="table_mat"/>
      <geom name="leg4" type="box" size="0.03 0.03 0.4" pos="0.7 0.5 -0.4" material="table_mat"/>
    </body>

    <camera name="track" mode="targetbody" target="table" pos="3 3 20"/>

    <body name="left_link0" pos="-0.4 0 0.42" childclass="panda_arm">
      <inertial mass="0.629769" pos="-0.041018 -0.00014 0.049974" fullinertia="0.00315 0.00388 0.004285 8.2904e-7 0.00015 8.2299e-6"/>
      <geom mesh="link0_0" material="off_white" class="visual"/>
      <geom mesh="link0_1" material="black" class="visual"/>
      <geom mesh="link0_2" material="off_white" class="visual"/>
      <geom mesh="link0_3" material="black" class="visual"/>
      <geom mesh="link0_4" material="off_white" class="visual"/>
      <geom mesh="link0_5" material="black" class="visual"/>
      <geom mesh="link0_7" material="white" class="visual"/>
      <geom mesh="link0_8" material="white" class="visual"/>
      <geom mesh="link0_9" material="black" class="visual"/>
      <geom mesh="link0_10" material="off_white" class="visual"/>
      <geom mesh="link0_11" material="white" class="visual"/>
      <geom mesh="link0_c" class="collision"/>
      <body name="left_link1" pos="0 0 0.333">
        <inertial mass="4.970684" pos="0.003875 0.002081 -0.04762" fullinertia="0.70337 0.70661 0.0091170 -0.00013900 0.0067720 0.019169"/>
        <joint name="left_joint1"/>
        <geom material="white" mesh="link1" class="visual"/>
        <geom mesh="link1_c" class="collision"/>
        <body name="left_link2" quat="1 -1 0 0">
          <inertial mass="0.646926" pos="-0.003141 -0.02872 0.003495" fullinertia="0.0079620 2.8110e-2 2.5995e-2 -3.925e-3 1.0254e-2 7.04e-4"/>
          <joint name="left_joint2"/>
          <geom material="white" mesh="link2" class="visual"/>
          <geom mesh="link2_c" class="collision"/>
          <body name="left_link3" pos="0 -0.316 0" quat="1 1 0 0">
            <joint name="left_joint3"/>
            <inertial mass="3.228604" pos="2.7518e-2 3.9252e-2 -6.6502e-2" fullinertia="3.7242e-2 3.6155e-2 1.083e-2 -4.761e-3 -1.1396e-2 -1.2805e-2"/>
            <geom mesh="link3_0" material="white" class="visual"/>
            <geom mesh="link3_1" material="white" class="visual"/>
            <geom mesh="link3_2" material="white" class="visual"/>
            <geom mesh="link3_3" material="black" class="visual"/>
            <geom mesh="link3_c" class="collision"/>
            <body name="left_link4" pos="0.0825 0 0" quat="1 1 0 0">
              <inertial mass="3.587895" pos="-5.317e-2 1.04419e-1 2.7454e-2" fullinertia="2.5853e-2 1.9552e-2 2.8323e-2 7.796e-3 -1.332e-3 8.641e-3"/>
              <joint name="left_joint4"/>
              <geom mesh="link4_0" material="white" class="visual"/>
              <geom mesh="link4_1" material="white" class="visual"/>
              <geom mesh="link4_2" material="black" class="visual"/>
              <geom mesh="link4_3" material="white" class="visual"/>
              <geom mesh="link4_c" class="collision"/>
              <body name="left_link5" pos="-0.0825 0.384 0" quat="1 -1 0 0">
                <inertial mass="1.225946" pos="-1.1953e-2 4.1065e-2 -3.8437e-2" fullinertia="3.5549e-2 2.9474e-2 8.627e-3 -2.117e-3 -4.037e-3 2.29e-4"/>
                <joint name="left_joint5"/>
                <geom mesh="link5_0" material="black" class="visual"/>
                <geom mesh="link5_1" material="white" class="visual"/>
                <geom mesh="link5_2" material="white" class="visual"/>
                <geom mesh="link5_c0" class="collision"/>
                <geom mesh="link5_c1" class="collision"/>
                <geom mesh="link5_c2" class="collision"/>
                <body name="left_link6" quat="1 1 0 0">
                  <inertial mass="1.666555" pos="6.0149e-2 -1.4117e-2 -1.0517e-2" fullinertia="1.964e-3 4.354e-3 5.433e-3 1.09e-4 -1.158e-3 3.41e-4"/>
                  <joint name="left_joint6"/>
                  <geom mesh="link6_0" material="off_white" class="visual"/>
                  <geom mesh="link6_1" material="white" class="visual"/>
                  <geom mesh="link6_2" material="black" class="visual"/>
                  <geom mesh="link6_3" material="white" class="visual"/>
                  <geom mesh="link6_4" material="white" class="visual"/>
                  <geom mesh="link6_5" material="white" class="visual"/>
                  <geom mesh="link6_6" material="white" class="visual"/>
                  <geom mesh="link6_7" material="light_blue" class="visual"/>
                  <geom mesh="link6_8" material="light_blue" class="visual"/>
                  <geom mesh="link6_9" material="black" class="visual"/>
                  <geom mesh="link6_10" material="black" class="visual"/>
                  <geom mesh="link6_11" material="white" class="visual"/>
                  <geom mesh="link6_12" material="green" class="visual"/>
                  <geom mesh="link6_13" material="white" class="visual"/>
                  <geom mesh="link6_14" material="black" class="visual"/>
                  <geom mesh="link6_15" material="black" class="visual"/>
                  <geom mesh="link6_16" material="white" class="visual"/>
                  <geom mesh="link6_c" class="collision"/>
                  <body name="left_link7" pos="0.088 0 0" quat="1 1 0 0">
                    <inertial mass="7.35522e-01" pos="1.0517e-2 -4.252e-3 6.1597e-2" fullinertia="1.2516e-2 1.0027e-2 4.815e-3 -4.28e-4 -1.196e-3 -7.41e-4"/>
                    <joint name="left_joint7"/>
                    <geom mesh="link7_0" material="white" class="visual"/>
                    <geom mesh="link7_1" material="black" class="visual"/>
                    <geom mesh="link7_2" material="black" class="visual"/>
                    <geom mesh="link7_3" material="black" class="visual"/>
                    <geom mesh="link7_4" material="black" class="visual"/>
                    <geom mesh="link7_5" material="black" class="visual"/>
                    <geom mesh="link7_6" material="black" class="visual"/>
                    <geom mesh="link7_7" material="white" class="visual"/>
                    <geom mesh="link7_c" class="collision"/>
                    <body name="left_hand" pos="0 0 0.107" quat="0.9238795 0 0 -0.3826834">
                      <inertial mass="0.73" pos="-0.01 0 0.03" diaginertia="0.001 0.0025 0.0017"/>
                      <geom mesh="hand_0" material="off_white" class="visual"/>
                      <geom mesh="hand_1" material="black" class="visual"/>
                      <geom mesh="hand_2" material="black" class="visual"/>
                      <geom mesh="hand_3" material="white" class="visual"/>
                      <geom mesh="hand_4" material="off_white" class="visual"/>
                      <geom mesh="hand_c" class="collision"/>
                      <body name="left_left_finger" pos="0 0 0.0584">
                        <inertial mass="0.015" pos="0 0 0" diaginertia="2.375e-6 2.375e-6 7.5e-7"/>
                        <joint name="left_finger_joint1" class="finger"/>
                        <geom mesh="finger_0" material="off_white" class="visual"/>
                        <geom mesh="finger_1" material="black" class="visual"/>
                        <geom mesh="finger_0" class="collision"/>
                        <geom class="fingertip_pad_collision_1"/>
                        <geom class="fingertip_pad_collision_2"/>
                        <geom class="fingertip_pad_collision_3"/>
                        <geom class="fingertip_pad_collision_4"/>
                        <geom class="fingertip_pad_collision_5"/>
                      </body>
                      <body name="left_right_finger" pos="0 0 0.0584" quat="0 0 0 1">
                        <inertial mass="0.015" pos="0 0 0" diaginertia="2.375e-6 2.375e-6 7.5e-7"/>
                        <joint name="left_finger_joint2" class="finger"/>
                        <geom mesh="finger_0" material="off_white" class="visual"/>
                        <geom mesh="finger_1" material="black" class="visual"/>
                        <geom mesh="finger_0" class="collision"/>
                        <geom class="fingertip_pad_collision_1"/>
                        <geom class="fingertip_pad_collision_2"/>
                        <geom class="fingertip_pad_collision_3"/>
                        <geom class="fingertip_pad_collision_4"/>
                        <geom class="fingertip_pad_collision_5"/>
                      </body>
                    </body>
                  </body>
                </body>
              </body>
            </body>
          </body>
        </body>
      </body>
    </body>

    <body name="right_link0" pos="0.4 0 0.42" quat="0 0 0 1" childclass="panda_arm">
      <inertial mass="0.629769" pos="-0.041018 -0.00014 0.049974" fullinertia="0.00315 0.00388 0.004285 8.2904e-7 0.00015 8.2299e-6"/>
      <geom mesh="link0_0" material="off_white" class="visual"/>
      <geom mesh="link0_1" material="black" class="visual"/>
      <geom mesh="link0_2" material="off_white" class="visual"/>
      <geom mesh="link0_3" material="black" class="visual"/>
      <geom mesh="link0_4" material="off_white" class="visual"/>
      <geom mesh="link0_5" material="black" class="visual"/>
      <geom mesh="link0_7" material="white" class="visual"/>
      <geom mesh="link0_8" material="white" class="visual"/>
      <geom mesh="link0_9" material="black" class="visual"/>
      <geom mesh="link0_10" material="off_white" class="visual"/>
      <geom mesh="link0_11" material="white" class="visual"/>
      <geom mesh="link0_c" class="collision"/>
      <body name="right_link1" pos="0 0 0.333">
        <inertial mass="4.970684" pos="0.003875 0.002081 -0.04762" fullinertia="0.70337 0.70661 0.0091170 -0.00013900 0.0067720 0.019169"/>
        <joint name="right_joint1"/>
        <geom material="white" mesh="link1" class="visual"/>
        <geom mesh="link1_c" class="collision"/>
        <body name="right_link2" quat="1 -1 0 0">
          <inertial mass="0.646926" pos="-0.003141 -0.02872 0.003495" fullinertia="0.0079620 2.8110e-2 2.5995e-2 -3.925e-3 1.0254e-2 7.04e-4"/>
          <joint name="right_joint2"/>
          <geom material="white" mesh="link2" class="visual"/>
          <geom mesh="link2_c" class="collision"/>
          <body name="right_link3" pos="0 -0.316 0" quat="1 1 0 0">
            <joint name="right_joint3"/>
            <inertial mass="3.228604" pos="2.7518e-2 3.9252e-2 -6.6502e-2" fullinertia="3.7242e-2 3.6155e-2 1.083e-2 -4.761e-3 -1.1396e-2 -1.2805e-2"/>
            <geom mesh="link3_0" material="white" class="visual"/>
            <geom mesh="link3_1" material="white" class="visual"/>
            <geom mesh="link3_2" material="white" class="visual"/>
            <geom mesh="link3_3" material="black" class="visual"/>
            <geom mesh="link3_c" class="collision"/>
            <body name="right_link4" pos="0.0825 0 0" quat="1 1 0 0">
              <inertial mass="3.587895" pos="-5.317e-2 1.04419e-1 2.7454e-2" fullinertia="2.5853e-2 1.9552e-2 2.8323e-2 7.796e-3 -1.332e-3 8.641e-3"/>
              <joint name="right_joint4"/>
              <geom mesh="link4_0" material="white" class="visual"/>
              <geom mesh="link4_1" material="white" class="visual"/>
              <geom mesh="link4_2" material="black" class="visual"/>
              <geom mesh="link4_3" material="white" class="visual"/>
              <geom mesh="link4_c" class="collision"/>
              <body name="right_link5" pos="-0.0825 0.384 0" quat="1 -1 0 0">
                <inertial mass="1.225946" pos="-1.1953e-2 4.1065e-2 -3.8437e-2" fullinertia="3.5549e-2 2.9474e-2 8.627e-3 -2.117e-3 -4.037e-3 2.29e-4"/>
                <joint name="right_joint5"/>
                <geom mesh="link5_0" material="black" class="visual"/>
                <geom mesh="link5_1" material="white" class="visual"/>
                <geom mesh="link5_2" material="white" class="visual"/>
                <geom mesh="link5_c0" class="collision"/>
                <geom mesh="link5_c1" class="collision"/>
                <geom mesh="link5_c2" class="collision"/>
                <body name="right_link6" quat="1 1 0 0">
                  <inertial mass="1.666555" pos="6.0149e-2 -1.4117e-2 -1.0517e-2" fullinertia="1.964e-3 4.354e-3 5.433e-3 1.09e-4 -1.158e-3 3.41e-4"/>
                  <joint name="right_joint6"/>
                  <geom mesh="link6_0" material="off_white" class="visual"/>
                  <geom mesh="link6_1" material="white" class="visual"/>
                  <geom mesh="link6_2" material="black" class="visual"/>
                  <geom mesh="link6_3" material="white" class="visual"/>
                  <geom mesh="link6_4" material="white" class="visual"/>
                  <geom mesh="link6_5" material="white" class="visual"/>
                  <geom mesh="link6_6" material="white" class="visual"/>
                  <geom mesh="link6_7" material="light_blue" class="visual"/>
                  <geom mesh="link6_8" material="light_blue" class="visual"/>
                  <geom mesh="link6_9" material="black" class="visual"/>
                  <geom mesh="link6_10" material="black" class="visual"/>
                  <geom mesh="link6_11" material="white" class="visual"/>
                  <geom mesh="link6_12" material="green" class="visual"/>
                  <geom mesh="link6_13" material="white" class="visual"/>
                  <geom mesh="link6_14" material="black" class="visual"/>
                  <geom mesh="link6_15" material="black" class="visual"/>
                  <geom mesh="link6_16" material="white" class="visual"/>
                  <geom mesh="link6_c" class="collision"/>
                  <body name="right_link7" pos="0.088 0 0" quat="1 1 0 0">
                    <inertial mass="7.35522e-01" pos="1.0517e-2 -4.252e-3 6.1597e-2" fullinertia="1.2516e-2 1.0027e-2 4.815e-3 -4.28e-4 -1.196e-3 -7.41e-4"/>
                    <joint name="right_joint7"/>
                    <geom mesh="link7_0" material="white" class="visual"/>
                    <geom mesh="link7_1" material="black" class="visual"/>
                    <geom mesh="link7_2" material="black" class="visual"/>
                    <geom mesh="link7_3" material="black" class="visual"/>
                    <geom mesh="link7_4" material="black" class="visual"/>
                    <geom mesh="link7_5" material="black" class="visual"/>
                    <geom mesh="link7_6" material="black" class="visual"/>
                    <geom mesh="link7_7" material="white" class="visual"/>
                    <geom mesh="link7_c" class="collision"/>
                    <body name="right_hand" pos="0 0 0.107" quat="0.9238795 0 0 -0.3826834">
                      <inertial mass="0.73" pos="-0.01 0 0.03" diaginertia="0.001 0.0025 0.0017"/>
                      <geom mesh="hand_0" material="off_white" class="visual"/>
                      <geom mesh="hand_1" material="black" class="visual"/>
                      <geom mesh="hand_2" material="black" class="visual"/>
                      <geom mesh="hand_3" material="white" class="visual"/>
                      <geom mesh="hand_4" material="off_white" class="visual"/>
                      <geom mesh="hand_c" class="collision"/>
                      <body name="right_left_finger" pos="0 0 0.0584">
                        <inertial mass="0.015" pos="0 0 0" diaginertia="2.375e-6 2.375e-6 7.5e-7"/>
                        <joint name="right_finger_joint1" class="finger"/>
                        <geom mesh="finger_0" material="off_white" class="visual"/>
                        <geom mesh="finger_1" material="black" class="visual"/>
                        <geom mesh="finger_0" class="collision"/>
                        <geom class="fingertip_pad_collision_1"/>
                        <geom class="fingertip_pad_collision_2"/>
                        <geom class="fingertip_pad_collision_3"/>
                        <geom class="fingertip_pad_collision_4"/>
                        <geom class="fingertip_pad_collision_5"/>
                      </body>
                      <body name="right_right_finger" pos="0 0 0.0584" quat="0 0 0 1">
                        <inertial mass="0.015" pos="0 0 0" diaginertia="2.375e-6 2.375e-6 7.5e-7"/>
                        <joint name="right_finger_joint2" class="finger"/>
                        <geom mesh="finger_0" material="off_white" class="visual"/>
                        <geom mesh="finger_1" material="black" class="visual"/>
                        <geom mesh="finger_0" class="collision"/>
                        <geom class="fingertip_pad_collision_1"/>
                        <geom class="fingertip_pad_collision_2"/>
                        <geom class="fingertip_pad_collision_3"/>
                        <geom class="fingertip_pad_collision_4"/>
                        <geom class="fingertip_pad_collision_5"/>
                      </body>
                    </body>
                  </body>
                </body>
              </body>
            </body>
          </body>
        </body>
      </body>
    </body>

    <body name="object" pos="0 0.3 0.45">
      <inertial mass="0.5" pos="0 0 -0.02" diaginertia="0.005 0.005 0.005"/>
      <joint type="free"/>

      <geom name="box_bottom" type="box" size="0.15 0.1 0.004" pos="0 0 -0.046"
            rgba="0.2 0.4 0.8 1" contype="1" conaffinity="1" friction="1.5 0.05 0.001" solimp="0.9 0.95 0.001"
            solref="0.02 1"/>

      <geom name="box_wall_front" type="box" size="0.004 0.1 0.05" pos="0.146 0 0"
            rgba="0.2 0.4 0.8 1" contype="1" conaffinity="1" friction="0.9 0.1 0.01" solimp="0.9 0.95 0.001"
            solref="0.02 1"/>

      <geom name="box_wall_back" type="box" size="0.004 0.1 0.05" pos="-0.146 0 0"
            rgba="0.2 0.4 0.8 1" contype="1" conaffinity="1" friction="0.9 0.1 0.01" solimp="0.9 0.95 0.001"
            solref="0.02 1"/>

      <geom name="box_wall_left" type="box" size="0.142 0.004 0.05" pos="0 0.096 0"
            rgba="0.2 0.4 0.8 1" contype="1" conaffinity="1" friction="0.9 0.1 0.01" solimp="0.9 0.95 0.001"
            solref="0.02 1"/>

      <geom name="box_wall_right" type="box" size="0.142 0.004 0.05" pos="0 -0.096 0"
            rgba="0.2 0.4 0.8 1" contype="1" conaffinity="1" friction="0.9 0.1 0.01" solimp="0.9 0.95 0.001"
            solref="0.02 1"/>
    </body>
  </worldbody>

  <tendon>
    <fixed name="left_split">
      <joint joint="left_finger_joint1" coef="0.6"/>
      <joint joint="left_finger_joint2" coef="0.6"/>
    </fixed>
    <fixed name="right_split">
      <joint joint="right_finger_joint1" coef="0.5"/>
      <joint joint="right_finger_joint2" coef="0.5"/>
    </fixed>
  </tendon>

  <equality>
    <joint joint1="left_finger_joint1" joint2="left_finger_joint2" solimp="0.95 0.99 0.001" solref="0.005 1"/>
    <joint joint1="right_finger_joint1" joint2="right_finger_joint2" solimp="0.95 0.99 0.001" solref="0.005 1"/>
  </equality>

  <actuator>
    <motor name="left_actuator1" joint="left_joint1" ctrlrange="-87 87"/>
    <motor name="left_actuator2" joint="left_joint2" ctrlrange="-87 87"/>
    <motor name="left_actuator3" joint="left_joint3" ctrlrange="-87 87"/>
    <motor name="left_actuator4" joint="left_joint4" ctrlrange="-87 87"/>
    <motor name="left_actuator5" joint="left_joint5" ctrlrange="-12 12"/>
    <motor name="left_actuator6" joint="left_joint6" ctrlrange="-12 12"/>
    <motor name="left_actuator7" joint="left_joint7" ctrlrange="-12 12"/>
    <general class="panda_arm"
             name="left_actuator8"
             tendon="left_split"
             dyntype="none"
             gaintype="fixed"
             gainprm="1"
             biasprm="0"
             forcerange="-40 40"
             ctrlrange="-40 40"/>

    <motor name="right_actuator1" joint="right_joint1" ctrlrange="-87 87"/>
    <motor name="right_actuator2" joint="right_joint2" ctrlrange="-87 87"/>
    <motor name="right_actuator3" joint="right_joint3" ctrlrange="-87 87"/>
    <motor name="right_actuator4" joint="right_joint4" ctrlrange="-87 87"/>
    <motor name="right_actuator5" joint="right_joint5" ctrlrange="-12 12"/>
    <motor name="right_actuator6" joint="right_joint6" ctrlrange="-12 12"/>
    <motor name="right_actuator7" joint="right_joint7" ctrlrange="-12 12"/>
    <general class="panda_arm"
             name="right_actuator8"
             tendon="right_split"
             dyntype="none"
             gaintype="fixed"
             gainprm="1"
             biasprm="0"
             forcerange="-40 40"
             ctrlrange="-40 40"/>
  </actuator>

  <keyframe>
    <key name="home_left" qpos="0 0 0 -1.57079 0 1.57079 -0.7853 0.04 0.04 0 0 0 -1.57079 0 1.57079 -0.7853 0.04 0.04 0 0.3 0.48 1 0 0 0"
         ctrl="0 0 0 0 0 0 0 30 0 0 0 0 0 0 0 30"/>
  </keyframe>

</mujoco>